<?xml version="1.0" ?>
<!-- =================================================================================== -->
<!-- |    This document was autogenerated by xacro from omni_1.urdf.xacro              | -->
<!-- |    EDITING THIS FILE BY HAND IS NOT RECOMMENDED                                 | -->
<!-- =================================================================================== -->
<robot name="omni_robot">
  <!-- MATERIAL DEFINITIONS -->
  <material name="white">
    <color rgba="1 1 1 1"/>
    <!-- White -->
  </material>
  <material name="copper">
    <color rgba="0.72 0.45 0.20 1"/>
    <!-- Copper -->
  </material>
  <!-- BASE LINK (CYLINDER) -->
  <link name="base_link">
    <visual>
      <origin rpy="0 0 0" xyz="0 0 0"/>
      <geometry>
        <cylinder length="0.064" radius="0.11"/>
        <!-- 220mm dia, 64mm height -->
      </geometry>
      <material name="white"/>
    </visual>
    <collision>
      <geometry>
        <cylinder length="0.064" radius="0.11"/>
      </geometry>
    </collision>
    <inertial>
      <mass value="1.0"/>
      <inertia ixx="0.001" ixy="0" ixz="0" iyy="0.001" iyz="0" izz="0.001"/>
    </inertial>
  </link>
  <!-- Main Wheel -->
  <link name="wheel_0">
    <visual>
      <origin rpy="0 1.5708 0" xyz="0 0 0"/>
      <!-- Wheel rotation -->
      <geometry>
        <cylinder length="0.02" radius="0.04"/>
        <!-- 80mm dia, 20mm thick -->
      </geometry>
      <material name="copper"/>
    </visual>
    <collision>
      <geometry>
        <cylinder length="0.02" radius="0.04"/>
      </geometry>
    </collision>
    <inertial>
      <mass value="0.15"/>
      <inertia ixx="0.0002" ixy="0" ixz="0" iyy="0.0002" iyz="0" izz="0.0002"/>
    </inertial>
  </link>
  <!-- Joint to Base -->
  <joint name="wheel_0_joint" type="continuous">
    <parent link="base_link"/>
    <child link="wheel_0"/>
    <origin rpy="0 0 0" xyz="0.13 0 -0.02"/>
    <axis xyz="1 0 0"/>
    <limit effort="10.0" velocity="10.0"/>
    <dynamics damping="0.1" friction="0.01"/>
  </joint>
  <!-- Roller 1: 0° -->
  <link name="wheel_0_roller_0">
    <visual>
      <origin rpy="0 0 0" xyz="0 0 0"/>
      <geometry>
        <cylinder length="0.02" radius="0.005"/>
      </geometry>
      <material name="white"/>
    </visual>
    <collision>
      <geometry>
        <cylinder length="0.02" radius="0.005"/>
      </geometry>
    </collision>
    <inertial>
      <mass value="0.01"/>
      <inertia ixx="0.00001" ixy="0" ixz="0" iyy="0.00001" iyz="0" izz="0.00001"/>
    </inertial>
  </link>
  <joint name="wheel_0_roller_0_joint" type="continuous">
    <parent link="wheel_0"/>
    <child link="wheel_0_roller_0"/>
    <origin rpy="0 0 0" xyz="0 0.04 0"/>
    <axis xyz="0 0 1"/>
    <!-- Roller spins around its own axis -->
    <limit effort="0.0" velocity="0.0"/>
    <dynamics damping="0.01" friction="0.01"/>
  </joint>
  <!-- Roller 2: 45° -->
  <link name="wheel_0_roller_45">
    <visual>
      <origin rpy="0 0 0" xyz="0 0 0"/>
      <geometry>
        <cylinder length="0.02" radius="0.005"/>
      </geometry>
      <material name="white"/>
    </visual>
    <collision>
      <geometry>
        <cylinder length="0.02" radius="0.005"/>
      </geometry>
    </collision>
    <inertial>
      <mass value="0.01"/>
      <inertia ixx="0.00001" ixy="0" ixz="0" iyy="0.00001" iyz="0" izz="0.00001"/>
    </inertial>
  </link>
  <joint name="wheel_0_roller_45_joint" type="continuous">
    <parent link="wheel_0"/>
    <child link="wheel_0_roller_45"/>
    <origin rpy="0.7854 0 0" xyz="0 0.028284 0.028284"/>
    <axis xyz="0 0 1"/>
    <limit effort="0.0" velocity="0.0"/>
    <dynamics damping="0.01" friction="0.01"/>
  </joint>
  <!-- Roller 3: 90° -->
  <link name="wheel_0_roller_90">
    <visual>
      <origin rpy="0 0 0" xyz="0 0 0"/>
      <geometry>
        <cylinder length="0.02" radius="0.005"/>
      </geometry>
      <material name="white"/>
    </visual>
    <collision>
      <geometry>
        <cylinder length="0.02" radius="0.005"/>
      </geometry>
    </collision>
    <inertial>
      <mass value="0.01"/>
      <inertia ixx="0.00001" ixy="0" ixz="0" iyy="0.00001" iyz="0" izz="0.00001"/>
    </inertial>
  </link>
  <joint name="wheel_0_roller_90_joint" type="continuous">
    <parent link="wheel_0"/>
    <child link="wheel_0_roller_90"/>
    <origin rpy="1.5708 0 0" xyz="0 0 0.04"/>
    <axis xyz="0 0 1"/>
    <limit effort="0.0" velocity="0.0"/>
    <dynamics damping="0.01" friction="0.01"/>
  </joint>
  <!-- Roller 4: 135° -->
  <link name="wheel_0_roller_135">
    <visual>
      <origin rpy="0 0 0" xyz="0 0 0"/>
      <geometry>
        <cylinder length="0.02" radius="0.005"/>
      </geometry>
      <material name="white"/>
    </visual>
    <collision>
      <geometry>
        <cylinder length="0.02" radius="0.005"/>
      </geometry>
    </collision>
    <inertial>
      <mass value="0.01"/>
      <inertia ixx="0.00001" ixy="0" ixz="0" iyy="0.00001" iyz="0" izz="0.00001"/>
    </inertial>
  </link>
  <joint name="wheel_0_roller_135_joint" type="continuous">
    <parent link="wheel_0"/>
    <child link="wheel_0_roller_135"/>
    <origin rpy="2.3562 0 0" xyz="0 -0.028284 0.028284"/>
    <axis xyz="0 0 1"/>
    <limit effort="0.0" velocity="0.0"/>
    <dynamics damping="0.01" friction="0.01"/>
  </joint>
  <!-- Roller 5: 180° -->
  <link name="wheel_0_roller_180">
    <visual>
      <origin rpy="0 0 0" xyz="0 0 0"/>
      <geometry>
        <cylinder length="0.02" radius="0.005"/>
      </geometry>
      <material name="white"/>
    </visual>
    <collision>
      <geometry>
        <cylinder length="0.02" radius="0.005"/>
      </geometry>
    </collision>
    <inertial>
      <mass value="0.01"/>
      <inertia ixx="0.00001" ixy="0" ixz="0" iyy="0.00001" iyz="0" izz="0.00001"/>
    </inertial>
  </link>
  <joint name="wheel_0_roller_180_joint" type="continuous">
    <parent link="wheel_0"/>
    <child link="wheel_0_roller_180"/>
    <origin rpy="0 0 0" xyz="0 -0.04 0"/>
    <axis xyz="0 1 0"/>
    <limit effort="0.0" velocity="0.0"/>
    <dynamics damping="0.01" friction="0.01"/>
  </joint>
  <!-- Roller 6: 225° -->
  <link name="wheel_0_roller_225">
    <visual>
      <origin rpy="0 0 0" xyz="0 0 0"/>
      <geometry>
        <cylinder length="0.02" radius="0.005"/>
      </geometry>
      <material name="white"/>
    </visual>
    <collision>
      <geometry>
        <cylinder length="0.02" radius="0.005"/>
      </geometry>
    </collision>
    <inertial>
      <mass value="0.01"/>
      <inertia ixx="0.00001" ixy="0" ixz="0" iyy="0.00001" iyz="0" izz="0.00001"/>
    </inertial>
  </link>
  <joint name="wheel_0_roller_225_joint" type="continuous">
    <parent link="wheel_0"/>
    <child link="wheel_0_roller_225"/>
    <origin rpy="0.7854 0 0" xyz="0 -0.028284 -0.028284"/>
    <axis xyz="0 0 1"/>
    <limit effort="0.0" velocity="0.0"/>
    <dynamics damping="0.01" friction="0.01"/>
  </joint>
  <!-- Roller 7: 270° -->
  <link name="wheel_0_roller_270">
    <visual>
      <origin rpy="0 0 0" xyz="0 0 0"/>
      <geometry>
        <cylinder length="0.02" radius="0.005"/>
      </geometry>
      <material name="white"/>
    </visual>
    <collision>
      <geometry>
        <cylinder length="0.02" radius="0.005"/>
      </geometry>
    </collision>
    <inertial>
      <mass value="0.01"/>
      <inertia ixx="0.00001" ixy="0" ixz="0" iyy="0.00001" iyz="0" izz="0.00001"/>
    </inertial>
  </link>
  <joint name="wheel_0_roller_270_joint" type="continuous">
    <parent link="wheel_0"/>
    <child link="wheel_0_roller_270"/>
    <origin rpy="1.5708 0 0" xyz="0 0 -0.04"/>
    <axis xyz="0 0 1"/>
    <limit effort="0.0" velocity="0.0"/>
    <dynamics damping="0.01" friction="0.01"/>
  </joint>
  <!-- Roller 8: 315° -->
  <link name="wheel_0_roller_315">
    <visual>
      <origin rpy="0 0 0" xyz="0 0 0"/>
      <geometry>
        <cylinder length="0.02" radius="0.005"/>
      </geometry>
      <material name="white"/>
    </visual>
    <collision>
      <geometry>
        <cylinder length="0.02" radius="0.005"/>
      </geometry>
    </collision>
    <inertial>
      <mass value="0.01"/>
      <inertia ixx="0.00001" ixy="0" ixz="0" iyy="0.00001" iyz="0" izz="0.00001"/>
    </inertial>
  </link>
  <joint name="wheel_0_roller_315_joint" type="continuous">
    <parent link="wheel_0"/>
    <child link="wheel_0_roller_315"/>
    <origin rpy="2.3562 0 0" xyz="0 0.028284 -0.028284"/>
    <axis xyz="0 0 1"/>
    <limit effort="0.0" velocity="0.0"/>
    <dynamics damping="0.01" friction="0.01"/>
  </joint>
  <!-- Main Wheel -->
  <link name="wheel_120">
    <visual>
      <origin rpy="0 1.5708 0" xyz="0 0 0"/>
      <!-- Wheel rotation -->
      <geometry>
        <cylinder length="0.02" radius="0.04"/>
        <!-- 80mm dia, 20mm thick -->
      </geometry>
      <material name="copper"/>
    </visual>
    <collision>
      <geometry>
        <cylinder length="0.02" radius="0.04"/>
      </geometry>
    </collision>
    <inertial>
      <mass value="0.15"/>
      <inertia ixx="0.0002" ixy="0" ixz="0" iyy="0.0002" iyz="0" izz="0.0002"/>
    </inertial>
  </link>
  <!-- Joint to Base -->
  <joint name="wheel_120_joint" type="continuous">
    <parent link="base_link"/>
    <child link="wheel_120"/>
    <origin rpy="0 0 2.0944" xyz="-0.065 0.11258 -0.02"/>
    <axis xyz="1 0 0"/>
    <limit effort="10.0" velocity="10.0"/>
    <dynamics damping="0.1" friction="0.01"/>
  </joint>
  <!-- Roller 1: 0° -->
  <link name="wheel_120_roller_0">
    <visual>
      <origin rpy="0 0 0" xyz="0 0 0"/>
      <geometry>
        <cylinder length="0.02" radius="0.005"/>
      </geometry>
      <material name="white"/>
    </visual>
    <collision>
      <geometry>
        <cylinder length="0.02" radius="0.005"/>
      </geometry>
    </collision>
    <inertial>
      <mass value="0.01"/>
      <inertia ixx="0.00001" ixy="0" ixz="0" iyy="0.00001" iyz="0" izz="0.00001"/>
    </inertial>
  </link>
  <joint name="wheel_120_roller_0_joint" type="continuous">
    <parent link="wheel_120"/>
    <child link="wheel_120_roller_0"/>
    <origin rpy="0 0 0" xyz="0 0.04 0"/>
    <axis xyz="0 0 1"/>
    <!-- Roller spins around its own axis -->
    <limit effort="0.0" velocity="0.0"/>
    <dynamics damping="0.01" friction="0.01"/>
  </joint>
  <!-- Roller 2: 45° -->
  <link name="wheel_120_roller_45">
    <visual>
      <origin rpy="0 0 0" xyz="0 0 0"/>
      <geometry>
        <cylinder length="0.02" radius="0.005"/>
      </geometry>
      <material name="white"/>
    </visual>
    <collision>
      <geometry>
        <cylinder length="0.02" radius="0.005"/>
      </geometry>
    </collision>
    <inertial>
      <mass value="0.01"/>
      <inertia ixx="0.00001" ixy="0" ixz="0" iyy="0.00001" iyz="0" izz="0.00001"/>
    </inertial>
  </link>
  <joint name="wheel_120_roller_45_joint" type="continuous">
    <parent link="wheel_120"/>
    <child link="wheel_120_roller_45"/>
    <origin rpy="0.7854 0 0" xyz="0 0.028284 0.028284"/>
    <axis xyz="0 0 1"/>
    <limit effort="0.0" velocity="0.0"/>
    <dynamics damping="0.01" friction="0.01"/>
  </joint>
  <!-- Roller 3: 90° -->
  <link name="wheel_120_roller_90">
    <visual>
      <origin rpy="0 0 0" xyz="0 0 0"/>
      <geometry>
        <cylinder length="0.02" radius="0.005"/>
      </geometry>
      <material name="white"/>
    </visual>
    <collision>
      <geometry>
        <cylinder length="0.02" radius="0.005"/>
      </geometry>
    </collision>
    <inertial>
      <mass value="0.01"/>
      <inertia ixx="0.00001" ixy="0" ixz="0" iyy="0.00001" iyz="0" izz="0.00001"/>
    </inertial>
  </link>
  <joint name="wheel_120_roller_90_joint" type="continuous">
    <parent link="wheel_120"/>
    <child link="wheel_120_roller_90"/>
    <origin rpy="1.5708 0 0" xyz="0 0 0.04"/>
    <axis xyz="0 0 1"/>
    <limit effort="0.0" velocity="0.0"/>
    <dynamics damping="0.01" friction="0.01"/>
  </joint>
  <!-- Roller 4: 135° -->
  <link name="wheel_120_roller_135">
    <visual>
      <origin rpy="0 0 0" xyz="0 0 0"/>
      <geometry>
        <cylinder length="0.02" radius="0.005"/>
      </geometry>
      <material name="white"/>
    </visual>
    <collision>
      <geometry>
        <cylinder length="0.02" radius="0.005"/>
      </geometry>
    </collision>
    <inertial>
      <mass value="0.01"/>
      <inertia ixx="0.00001" ixy="0" ixz="0" iyy="0.00001" iyz="0" izz="0.00001"/>
    </inertial>
  </link>
  <joint name="wheel_120_roller_135_joint" type="continuous">
    <parent link="wheel_120"/>
    <child link="wheel_120_roller_135"/>
    <origin rpy="2.3562 0 0" xyz="0 -0.028284 0.028284"/>
    <axis xyz="0 0 1"/>
    <limit effort="0.0" velocity="0.0"/>
    <dynamics damping="0.01" friction="0.01"/>
  </joint>
  <!-- Roller 5: 180° -->
  <link name="wheel_120_roller_180">
    <visual>
      <origin rpy="0 0 0" xyz="0 0 0"/>
      <geometry>
        <cylinder length="0.02" radius="0.005"/>
      </geometry>
      <material name="white"/>
    </visual>
    <collision>
      <geometry>
        <cylinder length="0.02" radius="0.005"/>
      </geometry>
    </collision>
    <inertial>
      <mass value="0.01"/>
      <inertia ixx="0.00001" ixy="0" ixz="0" iyy="0.00001" iyz="0" izz="0.00001"/>
    </inertial>
  </link>
  <joint name="wheel_120_roller_180_joint" type="continuous">
    <parent link="wheel_120"/>
    <child link="wheel_120_roller_180"/>
    <origin rpy="0 0 0" xyz="0 -0.04 0"/>
    <axis xyz="0 1 0"/>
    <limit effort="0.0" velocity="0.0"/>
    <dynamics damping="0.01" friction="0.01"/>
  </joint>
  <!-- Roller 6: 225° -->
  <link name="wheel_120_roller_225">
    <visual>
      <origin rpy="0 0 0" xyz="0 0 0"/>
      <geometry>
        <cylinder length="0.02" radius="0.005"/>
      </geometry>
      <material name="white"/>
    </visual>
    <collision>
      <geometry>
        <cylinder length="0.02" radius="0.005"/>
      </geometry>
    </collision>
    <inertial>
      <mass value="0.01"/>
      <inertia ixx="0.00001" ixy="0" ixz="0" iyy="0.00001" iyz="0" izz="0.00001"/>
    </inertial>
  </link>
  <joint name="wheel_120_roller_225_joint" type="continuous">
    <parent link="wheel_120"/>
    <child link="wheel_120_roller_225"/>
    <origin rpy="0.7854 0 0" xyz="0 -0.028284 -0.028284"/>
    <axis xyz="0 0 1"/>
    <limit effort="0.0" velocity="0.0"/>
    <dynamics damping="0.01" friction="0.01"/>
  </joint>
  <!-- Roller 7: 270° -->
  <link name="wheel_120_roller_270">
    <visual>
      <origin rpy="0 0 0" xyz="0 0 0"/>
      <geometry>
        <cylinder length="0.02" radius="0.005"/>
      </geometry>
      <material name="white"/>
    </visual>
    <collision>
      <geometry>
        <cylinder length="0.02" radius="0.005"/>
      </geometry>
    </collision>
    <inertial>
      <mass value="0.01"/>
      <inertia ixx="0.00001" ixy="0" ixz="0" iyy="0.00001" iyz="0" izz="0.00001"/>
    </inertial>
  </link>
  <joint name="wheel_120_roller_270_joint" type="continuous">
    <parent link="wheel_120"/>
    <child link="wheel_120_roller_270"/>
    <origin rpy="1.5708 0 0" xyz="0 0 -0.04"/>
    <axis xyz="0 0 1"/>
    <limit effort="0.0" velocity="0.0"/>
    <dynamics damping="0.01" friction="0.01"/>
  </joint>
  <!-- Roller 8: 315° -->
  <link name="wheel_120_roller_315">
    <visual>
      <origin rpy="0 0 0" xyz="0 0 0"/>
      <geometry>
        <cylinder length="0.02" radius="0.005"/>
      </geometry>
      <material name="white"/>
    </visual>
    <collision>
      <geometry>
        <cylinder length="0.02" radius="0.005"/>
      </geometry>
    </collision>
    <inertial>
      <mass value="0.01"/>
      <inertia ixx="0.00001" ixy="0" ixz="0" iyy="0.00001" iyz="0" izz="0.00001"/>
    </inertial>
  </link>
  <joint name="wheel_120_roller_315_joint" type="continuous">
    <parent link="wheel_120"/>
    <child link="wheel_120_roller_315"/>
    <origin rpy="2.3562 0 0" xyz="0 0.028284 -0.028284"/>
    <axis xyz="0 0 1"/>
    <limit effort="0.0" velocity="0.0"/>
    <dynamics damping="0.01" friction="0.01"/>
  </joint>
  <!-- Main Wheel -->
  <link name="wheel_240">
    <visual>
      <origin rpy="0 1.5708 0" xyz="0 0 0"/>
      <!-- Wheel rotation -->
      <geometry>
        <cylinder length="0.02" radius="0.04"/>
        <!-- 80mm dia, 20mm thick -->
      </geometry>
      <material name="copper"/>
    </visual>
    <collision>
      <geometry>
        <cylinder length="0.02" radius="0.04"/>
      </geometry>
    </collision>
    <inertial>
      <mass value="0.15"/>
      <inertia ixx="0.0002" ixy="0" ixz="0" iyy="0.0002" iyz="0" izz="0.0002"/>
    </inertial>
  </link>
  <!-- Joint to Base -->
  <joint name="wheel_240_joint" type="continuous">
    <parent link="base_link"/>
    <child link="wheel_240"/>
    <origin rpy="0 0 -2.0944" xyz="-0.065 -0.11258 -0.02"/>
    <axis xyz="1 0 0"/>
    <limit effort="10.0" velocity="10.0"/>
    <dynamics damping="0.1" friction="0.01"/>
  </joint>
  <!-- Roller 1: 0° -->
  <link name="wheel_240_roller_0">
    <visual>
      <origin rpy="0 0 0" xyz="0 0 0"/>
      <geometry>
        <cylinder length="0.02" radius="0.005"/>
      </geometry>
      <material name="white"/>
    </visual>
    <collision>
      <geometry>
        <cylinder length="0.02" radius="0.005"/>
      </geometry>
    </collision>
    <inertial>
      <mass value="0.01"/>
      <inertia ixx="0.00001" ixy="0" ixz="0" iyy="0.00001" iyz="0" izz="0.00001"/>
    </inertial>
  </link>
  <joint name="wheel_240_roller_0_joint" type="continuous">
    <parent link="wheel_240"/>
    <child link="wheel_240_roller_0"/>
    <origin rpy="0 0 0" xyz="0 0.04 0"/>
    <axis xyz="0 0 1"/>
    <!-- Roller spins around its own axis -->
    <limit effort="0.0" velocity="0.0"/>
    <dynamics damping="0.01" friction="0.01"/>
  </joint>
  <!-- Roller 2: 45° -->
  <link name="wheel_240_roller_45">
    <visual>
      <origin rpy="0 0 0" xyz="0 0 0"/>
      <geometry>
        <cylinder length="0.02" radius="0.005"/>
      </geometry>
      <material name="white"/>
    </visual>
    <collision>
      <geometry>
        <cylinder length="0.02" radius="0.005"/>
      </geometry>
    </collision>
    <inertial>
      <mass value="0.01"/>
      <inertia ixx="0.00001" ixy="0" ixz="0" iyy="0.00001" iyz="0" izz="0.00001"/>
    </inertial>
  </link>
  <joint name="wheel_240_roller_45_joint" type="continuous">
    <parent link="wheel_240"/>
    <child link="wheel_240_roller_45"/>
    <origin rpy="0.7854 0 0" xyz="0 0.028284 0.028284"/>
    <axis xyz="0 0 1"/>
    <limit effort="0.0" velocity="0.0"/>
    <dynamics damping="0.01" friction="0.01"/>
  </joint>
  <!-- Roller 3: 90° -->
  <link name="wheel_240_roller_90">
    <visual>
      <origin rpy="0 0 0" xyz="0 0 0"/>
      <geometry>
        <cylinder length="0.02" radius="0.005"/>
      </geometry>
      <material name="white"/>
    </visual>
    <collision>
      <geometry>
        <cylinder length="0.02" radius="0.005"/>
      </geometry>
    </collision>
    <inertial>
      <mass value="0.01"/>
      <inertia ixx="0.00001" ixy="0" ixz="0" iyy="0.00001" iyz="0" izz="0.00001"/>
    </inertial>
  </link>
  <joint name="wheel_240_roller_90_joint" type="continuous">
    <parent link="wheel_240"/>
    <child link="wheel_240_roller_90"/>
    <origin rpy="1.5708 0 0" xyz="0 0 0.04"/>
    <axis xyz="0 0 1"/>
    <limit effort="0.0" velocity="0.0"/>
    <dynamics damping="0.01" friction="0.01"/>
  </joint>
  <!-- Roller 4: 135° -->
  <link name="wheel_240_roller_135">
    <visual>
      <origin rpy="0 0 0" xyz="0 0 0"/>
      <geometry>
        <cylinder length="0.02" radius="0.005"/>
      </geometry>
      <material name="white"/>
    </visual>
    <collision>
      <geometry>
        <cylinder length="0.02" radius="0.005"/>
      </geometry>
    </collision>
    <inertial>
      <mass value="0.01"/>
      <inertia ixx="0.00001" ixy="0" ixz="0" iyy="0.00001" iyz="0" izz="0.00001"/>
    </inertial>
  </link>
  <joint name="wheel_240_roller_135_joint" type="continuous">
    <parent link="wheel_240"/>
    <child link="wheel_240_roller_135"/>
    <origin rpy="2.3562 0 0" xyz="0 -0.028284 0.028284"/>
    <axis xyz="0 0 1"/>
    <limit effort="0.0" velocity="0.0"/>
    <dynamics damping="0.01" friction="0.01"/>
  </joint>
  <!-- Roller 5: 180° -->
  <link name="wheel_240_roller_180">
    <visual>
      <origin rpy="0 0 0" xyz="0 0 0"/>
      <geometry>
        <cylinder length="0.02" radius="0.005"/>
      </geometry>
      <material name="white"/>
    </visual>
    <collision>
      <geometry>
        <cylinder length="0.02" radius="0.005"/>
      </geometry>
    </collision>
    <inertial>
      <mass value="0.01"/>
      <inertia ixx="0.00001" ixy="0" ixz="0" iyy="0.00001" iyz="0" izz="0.00001"/>
    </inertial>
  </link>
  <joint name="wheel_240_roller_180_joint" type="continuous">
    <parent link="wheel_240"/>
    <child link="wheel_240_roller_180"/>
    <origin rpy="0 0 0" xyz="0 -0.04 0"/>
    <axis xyz="0 1 0"/>
    <limit effort="0.0" velocity="0.0"/>
    <dynamics damping="0.01" friction="0.01"/>
  </joint>
  <!-- Roller 6: 225° -->
  <link name="wheel_240_roller_225">
    <visual>
      <origin rpy="0 0 0" xyz="0 0 0"/>
      <geometry>
        <cylinder length="0.02" radius="0.005"/>
      </geometry>
      <material name="white"/>
    </visual>
    <collision>
      <geometry>
        <cylinder length="0.02" radius="0.005"/>
      </geometry>
    </collision>
    <inertial>
      <mass value="0.01"/>
      <inertia ixx="0.00001" ixy="0" ixz="0" iyy="0.00001" iyz="0" izz="0.00001"/>
    </inertial>
  </link>
  <joint name="wheel_240_roller_225_joint" type="continuous">
    <parent link="wheel_240"/>
    <child link="wheel_240_roller_225"/>
    <origin rpy="0.7854 0 0" xyz="0 -0.028284 -0.028284"/>
    <axis xyz="0 0 1"/>
    <limit effort="0.0" velocity="0.0"/>
    <dynamics damping="0.01" friction="0.01"/>
  </joint>
  <!-- Roller 7: 270° -->
  <link name="wheel_240_roller_270">
    <visual>
      <origin rpy="0 0 0" xyz="0 0 0"/>
      <geometry>
        <cylinder length="0.02" radius="0.005"/>
      </geometry>
      <material name="white"/>
    </visual>
    <collision>
      <geometry>
        <cylinder length="0.02" radius="0.005"/>
      </geometry>
    </collision>
    <inertial>
      <mass value="0.01"/>
      <inertia ixx="0.00001" ixy="0" ixz="0" iyy="0.00001" iyz="0" izz="0.00001"/>
    </inertial>
  </link>
  <joint name="wheel_240_roller_270_joint" type="continuous">
    <parent link="wheel_240"/>
    <child link="wheel_240_roller_270"/>
    <origin rpy="1.5708 0 0" xyz="0 0 -0.04"/>
    <axis xyz="0 0 1"/>
    <limit effort="0.0" velocity="0.0"/>
    <dynamics damping="0.01" friction="0.01"/>
  </joint>
  <!-- Roller 8: 315° -->
  <link name="wheel_240_roller_315">
    <visual>
      <origin rpy="0 0 0" xyz="0 0 0"/>
      <geometry>
        <cylinder length="0.02" radius="0.005"/>
      </geometry>
      <material name="white"/>
    </visual>
    <collision>
      <geometry>
        <cylinder length="0.02" radius="0.005"/>
      </geometry>
    </collision>
    <inertial>
      <mass value="0.01"/>
      <inertia ixx="0.00001" ixy="0" ixz="0" iyy="0.00001" iyz="0" izz="0.00001"/>
    </inertial>
  </link>
  <joint name="wheel_240_roller_315_joint" type="continuous">
    <parent link="wheel_240"/>
    <child link="wheel_240_roller_315"/>
    <origin rpy="2.3562 0 0" xyz="0 0.028284 -0.028284"/>
    <axis xyz="0 0 1"/>
    <limit effort="0.0" velocity="0.0"/>
    <dynamics damping="0.01" friction="0.01"/>
  </joint>
  <!-- 240° -->
  <!-- WEBOTS SPECIFIC TAGS -->
  <webots>
    <device reference="wheel_0_joint" type="RotationalMotor"/>
    <device reference="wheel_120_joint" type="RotationalMotor"/>
    <device reference="wheel_240_joint" type="RotationalMotor"/>
  </webots>
</robot>
