<?xml version="1.0" ?>
<!-- =================================================================================== -->
<!-- |    This document was autogenerated by xacro from omni_1.urdf.xacro              | -->
<!-- |    EDITING THIS FILE BY HAND IS NOT RECOMMENDED                                 | -->
<!-- =================================================================================== -->
<robot name="omni_1">
  <!-- MATERIAL DEFINITIONS -->
  <material name="white">
    <color rgba="1 1 1 1"/>
    <!-- White -->
  </material>
  <material name="copper">
    <color rgba="0.72 0.45 0.20 1"/>
    <!-- Copper -->
  </material>
  <!-- BASE LINK (CYLINDER) -->
  <link name="base_link">
    <visual>
      <origin rpy="0 0 0" xyz="0 0 0"/>
      <geometry>
        <cylinder length="0.064" radius="0.11"/>
        <!-- 220mm dia, 64mm height -->
      </geometry>
      <material name="white"/>
    </visual>
    <collision>
      <geometry>
        <cylinder length="0.064" radius="0.11"/>
      </geometry>
    </collision>
    <inertial>
      <mass value="1.0"/>
      <inertia ixx="0.001" ixy="0" ixz="0" iyy="0.001" iyz="0" izz="0.001"/>
    </inertial>
  </link>
  <link name="wheel_0">
    <visual>
      <origin rpy="0 1.5708 0" xyz="0 0 0"/>
      <!-- Wheel rotation -->
      <geometry>
        <cylinder length="0.02" radius="0.04"/>
        <!-- 80mm dia, 20mm thick -->
      </geometry>
      <material name="copper"/>
    </visual>
    <!-- Roller 1: 0° -->
    <visual>
      <origin rpy="0 0 0" xyz="0 0.04 0"/>
      <geometry>
        <cylinder length="0.02" radius="0.005"/>
      </geometry>
      <material name="white"/>
      <!-- Explicitly set to white -->
    </visual>
    <!-- Roller 2: 45° -->
    <visual>
      <origin rpy="0.7854 0 0" xyz="0 0.028284219300449453 0.028284323194378944"/>
      <geometry>
        <cylinder length="0.02" radius="0.005"/>
      </geometry>
      <material name="white"/>
      <!-- Explicitly set to white -->
    </visual>
    <!-- Roller 3: 90° -->
    <visual>
      <origin rpy="1.5708 0 0" xyz="0 0 0.04"/>
      <geometry>
        <cylinder length="0.02" radius="0.005"/>
      </geometry>
      <material name="white"/>
      <!-- Explicitly set to white -->
    </visual>
    <!-- Roller 4: 135° -->
    <visual>
      <origin rpy="2.3562 0 0" xyz="0 -0.028284219300449453 0.028284323194378944"/>
      <geometry>
        <cylinder length="0.02" radius="0.005"/>
      </geometry>
      <material name="white"/>
      <!-- Explicitly set to white -->
    </visual>
    <!-- Roller 5: 180° -->
    <visual>
      <origin rpy="3.1416 0 0" xyz="0 -0.04 0"/>
      <geometry>
        <cylinder length="0.02" radius="0.005"/>
      </geometry>
      <material name="white"/>
      <!-- Explicitly set to white -->
    </visual>
    <!-- Roller 6: 225° -->
    <visual>
      <origin rpy="3.927 0 0" xyz="0 -0.028284219300449453 -0.028284323194378944"/>
      <geometry>
        <cylinder length="0.02" radius="0.005"/>
      </geometry>
      <material name="white"/>
      <!-- Explicitly set to white -->
    </visual>
    <!-- Roller 7: 270° -->
    <visual>
      <origin rpy="4.7124 0 0" xyz="0 0 -0.04"/>
      <geometry>
        <cylinder length="0.02" radius="0.005"/>
      </geometry>
      <material name="white"/>
      <!-- Explicitly set to white -->
    </visual>
    <!-- Roller 8: 315° -->
    <visual>
      <origin rpy="5.4978 0 0" xyz="0 0.028284219300449453 -0.028284323194378944"/>
      <geometry>
        <cylinder length="0.02" radius="0.005"/>
      </geometry>
      <material name="white"/>
      <!-- Explicitly set to white -->
    </visual>
    <collision>
      <geometry>
        <cylinder length="0.02" radius="0.04"/>
      </geometry>
    </collision>
    <inertial>
      <mass value="0.15"/>
      <inertia ixx="0.0002" ixy="0" ixz="0" iyy="0.0002" iyz="0" izz="0.0002"/>
    </inertial>
  </link>
  <!-- WHEEL ORIENTATION -->
  <joint name="wheel_0_joint" type="continuous">
    <parent link="base_link"/>
    <child link="wheel_0"/>
    <origin rpy="0 0 0" xyz="0.13 0 -0.02"/>
    <axis xyz="1 0 0"/>
  </joint>
  <link name="wheel_120">
    <visual>
      <origin rpy="0 1.5708 0" xyz="0 0 0"/>
      <!-- Wheel rotation -->
      <geometry>
        <cylinder length="0.02" radius="0.04"/>
        <!-- 80mm dia, 20mm thick -->
      </geometry>
      <material name="copper"/>
    </visual>
    <!-- Roller 1: 0° -->
    <visual>
      <origin rpy="0 0 0" xyz="0 0.04 0"/>
      <geometry>
        <cylinder length="0.02" radius="0.005"/>
      </geometry>
      <material name="white"/>
      <!-- Explicitly set to white -->
    </visual>
    <!-- Roller 2: 45° -->
    <visual>
      <origin rpy="0.7854 0 0" xyz="0 0.028284219300449453 0.028284323194378944"/>
      <geometry>
        <cylinder length="0.02" radius="0.005"/>
      </geometry>
      <material name="white"/>
      <!-- Explicitly set to white -->
    </visual>
    <!-- Roller 3: 90° -->
    <visual>
      <origin rpy="1.5708 0 0" xyz="0 0 0.04"/>
      <geometry>
        <cylinder length="0.02" radius="0.005"/>
      </geometry>
      <material name="white"/>
      <!-- Explicitly set to white -->
    </visual>
    <!-- Roller 4: 135° -->
    <visual>
      <origin rpy="2.3562 0 0" xyz="0 -0.028284219300449453 0.028284323194378944"/>
      <geometry>
        <cylinder length="0.02" radius="0.005"/>
      </geometry>
      <material name="white"/>
      <!-- Explicitly set to white -->
    </visual>
    <!-- Roller 5: 180° -->
    <visual>
      <origin rpy="3.1416 0 0" xyz="0 -0.04 0"/>
      <geometry>
        <cylinder length="0.02" radius="0.005"/>
      </geometry>
      <material name="white"/>
      <!-- Explicitly set to white -->
    </visual>
    <!-- Roller 6: 225° -->
    <visual>
      <origin rpy="3.927 0 0" xyz="0 -0.028284219300449453 -0.028284323194378944"/>
      <geometry>
        <cylinder length="0.02" radius="0.005"/>
      </geometry>
      <material name="white"/>
      <!-- Explicitly set to white -->
    </visual>
    <!-- Roller 7: 270° -->
    <visual>
      <origin rpy="4.7124 0 0" xyz="0 0 -0.04"/>
      <geometry>
        <cylinder length="0.02" radius="0.005"/>
      </geometry>
      <material name="white"/>
      <!-- Explicitly set to white -->
    </visual>
    <!-- Roller 8: 315° -->
    <visual>
      <origin rpy="5.4978 0 0" xyz="0 0.028284219300449453 -0.028284323194378944"/>
      <geometry>
        <cylinder length="0.02" radius="0.005"/>
      </geometry>
      <material name="white"/>
      <!-- Explicitly set to white -->
    </visual>
    <collision>
      <geometry>
        <cylinder length="0.02" radius="0.04"/>
      </geometry>
    </collision>
    <inertial>
      <mass value="0.15"/>
      <inertia ixx="0.0002" ixy="0" ixz="0" iyy="0.0002" iyz="0" izz="0.0002"/>
    </inertial>
  </link>
  <!-- WHEEL ORIENTATION -->
  <joint name="wheel_120_joint" type="continuous">
    <parent link="base_link"/>
    <child link="wheel_120"/>
    <origin rpy="0 0 2.0944" xyz="-0.065 0.11258 -0.02"/>
    <axis xyz="1 0 0"/>
  </joint>
  <link name="wheel_240">
    <visual>
      <origin rpy="0 1.5708 0" xyz="0 0 0"/>
      <!-- Wheel rotation -->
      <geometry>
        <cylinder length="0.02" radius="0.04"/>
        <!-- 80mm dia, 20mm thick -->
      </geometry>
      <material name="copper"/>
    </visual>
    <!-- Roller 1: 0° -->
    <visual>
      <origin rpy="0 0 0" xyz="0 0.04 0"/>
      <geometry>
        <cylinder length="0.02" radius="0.005"/>
      </geometry>
      <material name="white"/>
      <!-- Explicitly set to white -->
    </visual>
    <!-- Roller 2: 45° -->
    <visual>
      <origin rpy="0.7854 0 0" xyz="0 0.028284219300449453 0.028284323194378944"/>
      <geometry>
        <cylinder length="0.02" radius="0.005"/>
      </geometry>
      <material name="white"/>
      <!-- Explicitly set to white -->
    </visual>
    <!-- Roller 3: 90° -->
    <visual>
      <origin rpy="1.5708 0 0" xyz="0 0 0.04"/>
      <geometry>
        <cylinder length="0.02" radius="0.005"/>
      </geometry>
      <material name="white"/>
      <!-- Explicitly set to white -->
    </visual>
    <!-- Roller 4: 135° -->
    <visual>
      <origin rpy="2.3562 0 0" xyz="0 -0.028284219300449453 0.028284323194378944"/>
      <geometry>
        <cylinder length="0.02" radius="0.005"/>
      </geometry>
      <material name="white"/>
      <!-- Explicitly set to white -->
    </visual>
    <!-- Roller 5: 180° -->
    <visual>
      <origin rpy="3.1416 0 0" xyz="0 -0.04 0"/>
      <geometry>
        <cylinder length="0.02" radius="0.005"/>
      </geometry>
      <material name="white"/>
      <!-- Explicitly set to white -->
    </visual>
    <!-- Roller 6: 225° -->
    <visual>
      <origin rpy="3.927 0 0" xyz="0 -0.028284219300449453 -0.028284323194378944"/>
      <geometry>
        <cylinder length="0.02" radius="0.005"/>
      </geometry>
      <material name="white"/>
      <!-- Explicitly set to white -->
    </visual>
    <!-- Roller 7: 270° -->
    <visual>
      <origin rpy="4.7124 0 0" xyz="0 0 -0.04"/>
      <geometry>
        <cylinder length="0.02" radius="0.005"/>
      </geometry>
      <material name="white"/>
      <!-- Explicitly set to white -->
    </visual>
    <!-- Roller 8: 315° -->
    <visual>
      <origin rpy="5.4978 0 0" xyz="0 0.028284219300449453 -0.028284323194378944"/>
      <geometry>
        <cylinder length="0.02" radius="0.005"/>
      </geometry>
      <material name="white"/>
      <!-- Explicitly set to white -->
    </visual>
    <collision>
      <geometry>
        <cylinder length="0.02" radius="0.04"/>
      </geometry>
    </collision>
    <inertial>
      <mass value="0.15"/>
      <inertia ixx="0.0002" ixy="0" ixz="0" iyy="0.0002" iyz="0" izz="0.0002"/>
    </inertial>
  </link>
  <!-- WHEEL ORIENTATION -->
  <joint name="wheel_240_joint" type="continuous">
    <parent link="base_link"/>
    <child link="wheel_240"/>
    <origin rpy="0 0 -2.0944" xyz="-0.065 -0.11258 -0.02"/>
    <axis xyz="1 0 0"/>
  </joint>
  <!-- 240° -->
</robot>
